<?xml version="1.0" ?>
<!-- =================================================================================== -->
<!-- |    This document was autogenerated by xacro from abb4600_arm.xacro              | -->
<!-- |    EDITING THIS FILE BY HAND IS NOT RECOMMENDED                                 | -->
<!-- =================================================================================== -->
<robot name="abb4600_arm">
  <material name="silver_default">
    <color rgba="0.700 0.700 0.700 1.000"/>
  </material>
  <material name="opaque215215215">
    <color rgba="0.8431372549019608 0.8431372549019608 0.8431372549019608 1.0"/>
  </material>
  <material name="opaque128128128">
    <color rgba="0.5019607843137255 0.5019607843137255 0.5019607843137255 1.0"/>
  </material>
  <transmission name="joint1_tran">
    <type>transmission_interface/SimpleTransmission</type>
    <joint name="joint1">
      <hardwareInterface>hardware_interface/EffortJointInterface</hardwareInterface>
    </joint>
    <actuator name="joint1_actr">
      <hardwareInterface>hardware_interface/EffortJointInterface</hardwareInterface>
      <mechanicalReduction>1</mechanicalReduction>
    </actuator>
  </transmission>
  <transmission name="joint2_tran">
    <type>transmission_interface/SimpleTransmission</type>
    <joint name="joint2">
      <hardwareInterface>hardware_interface/EffortJointInterface</hardwareInterface>
    </joint>
    <actuator name="joint2_actr">
      <hardwareInterface>hardware_interface/EffortJointInterface</hardwareInterface>
      <mechanicalReduction>1</mechanicalReduction>
    </actuator>
  </transmission>
  <transmission name="joint3_tran">
    <type>transmission_interface/SimpleTransmission</type>
    <joint name="joint3">
      <hardwareInterface>hardware_interface/EffortJointInterface</hardwareInterface>
    </joint>
    <actuator name="joint3_actr">
      <hardwareInterface>hardware_interface/EffortJointInterface</hardwareInterface>
      <mechanicalReduction>1</mechanicalReduction>
    </actuator>
  </transmission>
  <transmission name="joint4_tran">
    <type>transmission_interface/SimpleTransmission</type>
    <joint name="joint4">
      <hardwareInterface>hardware_interface/EffortJointInterface</hardwareInterface>
    </joint>
    <actuator name="joint4_actr">
      <hardwareInterface>hardware_interface/EffortJointInterface</hardwareInterface>
      <mechanicalReduction>1</mechanicalReduction>
    </actuator>
  </transmission>
  <transmission name="joint5_tran">
    <type>transmission_interface/SimpleTransmission</type>
    <joint name="joint5">
      <hardwareInterface>hardware_interface/EffortJointInterface</hardwareInterface>
    </joint>
    <actuator name="joint5_actr">
      <hardwareInterface>hardware_interface/EffortJointInterface</hardwareInterface>
      <mechanicalReduction>1</mechanicalReduction>
    </actuator>
  </transmission>
  <transmission name="joint6_tran">
    <type>transmission_interface/SimpleTransmission</type>
    <joint name="joint6">
      <hardwareInterface>hardware_interface/EffortJointInterface</hardwareInterface>
    </joint>
    <actuator name="joint6_actr">
      <hardwareInterface>hardware_interface/EffortJointInterface</hardwareInterface>
      <mechanicalReduction>1</mechanicalReduction>
    </actuator>
  </transmission>
  <gazebo>
    <plugin filename="libgazebo_ros_control.so" name="control"/>
  </gazebo>
  <gazebo reference="base_link">
    <material>Gazebo/Silver</material>
    <mu1>0.2</mu1>
    <mu2>0.2</mu2>
    <selfCollide>true</selfCollide>
    <gravity>true</gravity>
  </gazebo>
  <gazebo reference="link1_1">
    <material>Gazebo/Silver</material>
    <mu1>0.2</mu1>
    <mu2>0.2</mu2>
    <selfCollide>true</selfCollide>
  </gazebo>
  <gazebo reference="link2_1">
    <material>Gazebo/Silver</material>
    <mu1>0.2</mu1>
    <mu2>0.2</mu2>
    <selfCollide>true</selfCollide>
  </gazebo>
  <gazebo reference="link3_1">
    <material>Gazebo/Silver</material>
    <mu1>0.2</mu1>
    <mu2>0.2</mu2>
    <selfCollide>true</selfCollide>
  </gazebo>
  <gazebo reference="link4_1">
    <material>Gazebo/Silver</material>
    <mu1>0.2</mu1>
    <mu2>0.2</mu2>
    <selfCollide>true</selfCollide>
  </gazebo>
  <gazebo reference="link5_1">
    <material>Gazebo/Silver</material>
    <mu1>0.2</mu1>
    <mu2>0.2</mu2>
    <selfCollide>true</selfCollide>
  </gazebo>
  <gazebo reference="link6_1">
    <material>Gazebo/Silver</material>
    <mu1>0.2</mu1>
    <mu2>0.2</mu2>
    <selfCollide>true</selfCollide>
  </gazebo>
  <link name="base_link">
    <inertial>
      <origin rpy="0 0 0" xyz="0.5388065719683329 0.0003632766666347196 0.6099645348312986"/>
      <mass value="237.71328449710663"/>
      <inertia ixx="3.322456" ixy="0.030784" ixz="0.455197" iyy="6.746895" iyz="0.001141" izz="9.112071"/>
    </inertial>
    <visual>
      <origin rpy="0 0 0" xyz="0 0 0"/>
      <geometry>
        <mesh filename="package://abb4600_arm_description/meshes/base_link.stl" scale="0.001 0.001 0.001"/>
      </geometry>
      <material name="opaque215215215"/>
    </visual>
    <collision>
      <origin rpy="0 0 0" xyz="0 0 0"/>
      <geometry>
        <mesh filename="package://abb4600_arm_description/meshes/base_link.stl" scale="0.001 0.001 0.001"/>
      </geometry>
    </collision>
  </link>
  <link name="link1_1">
    <inertial>
      <origin rpy="0 0 0" xyz="0.07703823314609848 0.024690140056912023 0.24069844675200514"/>
      <mass value="332.94668738623227"/>
      <inertia ixx="8.732817" ixy="-0.760548" ixz="-2.349543" iyy="11.378243" iyz="-0.812185" izz="9.105966"/>
    </inertial>
    <visual>
      <origin rpy="0 0 0" xyz="-0.63 -0.0 -0.687"/>
      <geometry>
        <mesh filename="package://abb4600_arm_description/meshes/link1_1.stl" scale="0.001 0.001 0.001"/>
      </geometry>
      <material name="opaque215215215"/>
    </visual>
    <collision>
      <origin rpy="0 0 0" xyz="-0.63 -0.0 -0.687"/>
      <geometry>
        <mesh filename="package://abb4600_arm_description/meshes/link1_1.stl" scale="0.001 0.001 0.001"/>
      </geometry>
    </collision>
  </link>
  <link name="link2_1">
    <inertial>
      <origin rpy="0 0 0" xyz="8.11885680672697e-05 -0.04807041025187958 0.3967756795501174"/>
      <mass value="220.41574953890478"/>
      <inertia ixx="17.032393" ixy="-0.000225" ixz="0.002216" iyy="17.64881" iyz="0.57807" izz="1.263078"/>
    </inertial>
    <visual>
      <origin rpy="0 0 0" xyz="-0.805 0.1225 -1.0225"/>
      <geometry>
        <mesh filename="package://abb4600_arm_description/meshes/link2_1.stl" scale="0.001 0.001 0.001"/>
      </geometry>
      <material name="opaque215215215"/>
    </visual>
    <collision>
      <origin rpy="0 0 0" xyz="-0.805 0.1225 -1.0225"/>
      <geometry>
        <mesh filename="package://abb4600_arm_description/meshes/link2_1.stl" scale="0.001 0.001 0.001"/>
      </geometry>
    </collision>
  </link>
  <link name="link3_1">
    <inertial>
      <origin rpy="0 0 0" xyz="0.04071239379184699 0.19846613160738472 0.11876191185100127"/>
      <mass value="400.49713290737077"/>
      <inertia ixx="8.894012" ixy="0.577243" ixz="-0.921523" iyy="10.88805" iyz="-0.110796" izz="8.946828"/>
    </inertial>
    <visual>
      <origin rpy="0 0 0" xyz="-0.805 0.1492 -1.9225"/>
      <geometry>
        <mesh filename="package://abb4600_arm_description/meshes/link3_1.stl" scale="0.001 0.001 0.001"/>
      </geometry>
      <material name="opaque215215215"/>
    </visual>
    <collision>
      <origin rpy="0 0 0" xyz="-0.805 0.1492 -1.9225"/>
      <geometry>
        <mesh filename="package://abb4600_arm_description/meshes/link3_1.stl" scale="0.001 0.001 0.001"/>
      </geometry>
    </collision>
  </link>
  <link name="link4_1">
    <inertial>
      <origin rpy="0 0 0" xyz="0.39313278775216975 -0.0019755165564121586 -0.0028460250959141398"/>
      <mass value="87.24410051263554"/>
      <inertia ixx="0.418056" ixy="0.044331" ixz="0.017987" iyy="3.624528" iyz="0.000226" izz="3.763023"/>
    </inertial>
    <visual>
      <origin rpy="0 0 0" xyz="-1.1451 -0.0 -2.0975"/>
      <geometry>
        <mesh filename="package://abb4600_arm_description/meshes/link4_1.stl" scale="0.001 0.001 0.001"/>
      </geometry>
      <material name="opaque215215215"/>
    </visual>
    <collision>
      <origin rpy="0 0 0" xyz="-1.1451 -0.0 -2.0975"/>
      <geometry>
        <mesh filename="package://abb4600_arm_description/meshes/link4_1.stl" scale="0.001 0.001 0.001"/>
      </geometry>
    </collision>
  </link>
  <link name="link5_1">
    <inertial>
      <origin rpy="0 0 0" xyz="-0.0010508027520477192 -0.06745153171005737 0.00040028149794890666"/>
      <mass value="11.796293100629127"/>
      <inertia ixx="0.023766" ixy="-6e-06" ixz="-0.000134" iyy="0.024654" iyz="-4e-05" izz="0.026174"/>
    </inertial>
    <visual>
      <origin rpy="0 0 0" xyz="-1.765 -0.064 -2.0975"/>
      <geometry>
        <mesh filename="package://abb4600_arm_description/meshes/link5_1.stl" scale="0.001 0.001 0.001"/>
      </geometry>
      <material name="opaque215215215"/>
    </visual>
    <collision>
      <origin rpy="0 0 0" xyz="-1.765 -0.064 -2.0975"/>
      <geometry>
        <mesh filename="package://abb4600_arm_description/meshes/link5_1.stl" scale="0.001 0.001 0.001"/>
      </geometry>
    </collision>
  </link>
  <link name="link6_1">
    <inertial>
      <origin rpy="0 0 0" xyz="0.04834499414174176 -0.00028927280581593517 0.00013855618719471607"/>
      <mass value="2.0887598324758585"/>
      <inertia ixx="0.002956" ixy="6e-06" ixz="-2e-06" iyy="0.002242" iyz="-2.1e-05" izz="0.002257"/>
    </inertial>
    <visual>
      <origin rpy="0 0 0" xyz="-1.83 -0.0 -2.0975"/>
      <geometry>
        <mesh filename="package://abb4600_arm_description/meshes/link6_1.stl" scale="0.001 0.001 0.001"/>
      </geometry>
      <material name="opaque128128128"/>
    </visual>
    <collision>
      <origin rpy="0 0 0" xyz="-1.83 -0.0 -2.0975"/>
      <geometry>
        <mesh filename="package://abb4600_arm_description/meshes/link6_1.stl" scale="0.001 0.001 0.001"/>
      </geometry>
    </collision>
  </link>
  <joint name="joint1" type="continuous">
    <origin rpy="0 0 0" xyz="0.63 0.0 0.687"/>
    <parent link="base_link"/>
    <child link="link1_1"/>
    <axis xyz="-0.0 -0.0 1.0"/>
  </joint>
  <joint name="joint2" type="continuous">
    <origin rpy="0 0 0" xyz="0.175 -0.1225 0.3355"/>
    <parent link="link1_1"/>
    <child link="link2_1"/>
    <axis xyz="-0.0 -1.0 -0.0"/>
  </joint>
  <joint name="joint3" type="continuous">
    <origin rpy="0 0 0" xyz="0.0 -0.0267 0.9"/>
    <parent link="link2_1"/>
    <child link="link3_1"/>
    <axis xyz="-0.0 -1.0 -0.0"/>
  </joint>
  <joint name="joint4" type="continuous">
    <origin rpy="0 0 0" xyz="0.3401 0.1492 0.175"/>
    <parent link="link3_1"/>
    <child link="link4_1"/>
    <axis xyz="1.0 0.0 -0.0"/>
  </joint>
  <joint name="joint5" type="continuous">
    <origin rpy="0 0 0" xyz="0.6199 0.064 0.0"/>
    <parent link="link4_1"/>
    <child link="link5_1"/>
    <axis xyz="0.0 -1.0 -0.0"/>
  </joint>
  <joint name="joint6" type="continuous">
    <origin rpy="0 0 0" xyz="0.065 -0.064 0.0"/>
    <parent link="link5_1"/>
    <child link="link6_1"/>
    <axis xyz="1.0 0.0 -0.0"/>
  </joint>
</robot>
