<?xml version="1.0" ?>
<!-- =================================================================================== -->
<!-- |    This document was autogenerated by xacro from eoat.xacro                     | -->
<!-- |    EDITING THIS FILE BY HAND IS NOT RECOMMENDED                                 | -->
<!-- =================================================================================== -->
<robot name="eoat">
  <material name="silver_default">
    <color rgba="0.700 0.700 0.700 1.000"/>
  </material>
  <material name="paint_metallic_red">
    <color rgba="0.7686274509803922 0.20784313725490197 0.15294117647058825 1.0"/>
  </material>
  <material name="paint_metallic_silver">
    <color rgba="0.984313725490196 0.9803921568627451 0.9607843137254902 1.0"/>
  </material>
  <material name="paint_metallic_blue">
    <color rgba="0.18823529411764706 0.23137254901960785 0.5882352941176471 1.0"/>
  </material>
  <material name="polymide_kapton">
    <color rgba="0.7843137254901961 0.5568627450980392 0.027450980392156862 1.0"/>
  </material>
  <transmission name="boxSupport_joint_tran">
    <type>transmission_interface/SimpleTransmission</type>
    <joint name="boxSupport_joint">
      <hardwareInterface>hardware_interface/EffortJointInterface</hardwareInterface>
    </joint>
    <actuator name="boxSupport_joint_actr">
      <hardwareInterface>hardware_interface/EffortJointInterface</hardwareInterface>
      <mechanicalReduction>1</mechanicalReduction>
    </actuator>
  </transmission>
  <transmission name="suctionLifter_joint_tran">
    <type>transmission_interface/SimpleTransmission</type>
    <joint name="suctionLifter_joint">
      <hardwareInterface>hardware_interface/EffortJointInterface</hardwareInterface>
    </joint>
    <actuator name="suctionLifter_joint_actr">
      <hardwareInterface>hardware_interface/EffortJointInterface</hardwareInterface>
      <mechanicalReduction>1</mechanicalReduction>
    </actuator>
  </transmission>
  <transmission name="suction_joint_tran">
    <type>transmission_interface/SimpleTransmission</type>
    <joint name="suction_joint">
      <hardwareInterface>hardware_interface/EffortJointInterface</hardwareInterface>
    </joint>
    <actuator name="suction_joint_actr">
      <hardwareInterface>hardware_interface/EffortJointInterface</hardwareInterface>
      <mechanicalReduction>1</mechanicalReduction>
    </actuator>
  </transmission>
  <transmission name="padRotate_joint_tran">
    <type>transmission_interface/SimpleTransmission</type>
    <joint name="padRotate_joint">
      <hardwareInterface>hardware_interface/EffortJointInterface</hardwareInterface>
    </joint>
    <actuator name="padRotate_joint_actr">
      <hardwareInterface>hardware_interface/EffortJointInterface</hardwareInterface>
      <mechanicalReduction>1</mechanicalReduction>
    </actuator>
  </transmission>
  <gazebo>
    <plugin filename="libgazebo_ros_control.so" name="control"/>
  </gazebo>
  <gazebo reference="base_link">
    <material>Gazebo/Silver</material>
    <mu1>0.2</mu1>
    <mu2>0.2</mu2>
    <selfCollide>true</selfCollide>
    <gravity>true</gravity>
  </gazebo>
  <gazebo reference="LARGE_PAD_LIFTER_1">
    <material>Gazebo/Silver</material>
    <mu1>0.2</mu1>
    <mu2>0.2</mu2>
    <selfCollide>true</selfCollide>
  </gazebo>
  <gazebo reference="SMALL_PAD_LIFTER_1">
    <material>Gazebo/Silver</material>
    <mu1>0.2</mu1>
    <mu2>0.2</mu2>
    <selfCollide>true</selfCollide>
  </gazebo>
  <gazebo reference="SMALL_PAD_1">
    <material>Gazebo/Silver</material>
    <mu1>0.2</mu1>
    <mu2>0.2</mu2>
    <selfCollide>true</selfCollide>
  </gazebo>
  <gazebo reference="LARGE_PAD_1">
    <material>Gazebo/Silver</material>
    <mu1>0.2</mu1>
    <mu2>0.2</mu2>
    <selfCollide>true</selfCollide>
  </gazebo>
  <gazebo reference="camera_1">
    <material>Gazebo/Silver</material>
    <mu1>0.2</mu1>
    <mu2>0.2</mu2>
    <selfCollide>true</selfCollide>
  </gazebo>
  <link name="base_link">
    <inertial>
      <origin rpy="0 0 0" xyz="-0.0013655188721125974 -0.09999111481847915 0.06942952989988299"/>
      <mass value="15.51108141594419"/>
      <inertia ixx="0.275049" ixy="0.008744" ixz="-6.7e-05" iyy="0.112146" iyz="-0.02779" izz="0.25806"/>
    </inertial>
    <visual>
      <origin rpy="0 0 0" xyz="0 0 0"/>
      <geometry>
        <mesh filename="package://eoat_description/meshes/base_link.stl" scale="0.001 0.001 0.001"/>
      </geometry>
      <material name="paint_metallic_blue"/>
    </visual>
    <collision>
      <origin rpy="0 0 0" xyz="0 0 0"/>
      <geometry>
        <mesh filename="package://eoat_description/meshes/base_link.stl" scale="0.001 0.001 0.001"/>
      </geometry>
    </collision>
  </link>
  <link name="LARGE_PAD_LIFTER_1">
    <inertial>
      <origin rpy="0 0 0" xyz="2.739799308567985e-07 -0.01887908495888596 0.01569535162540217"/>
      <mass value="2.5776810090097073"/>
      <inertia ixx="0.016363" ixy="-0.0" ixz="0.0" iyy="0.021404" iyz="0.003611" izz="0.019622"/>
    </inertial>
    <visual>
      <origin rpy="0 0 0" xyz="0.001678 0.260502 -0.133561"/>
      <geometry>
        <mesh filename="package://eoat_description/meshes/LARGE_PAD_LIFTER_1.stl" scale="0.001 0.001 0.001"/>
      </geometry>
      <material name="paint_metallic_silver"/>
    </visual>
    <collision>
      <origin rpy="0 0 0" xyz="0.001678 0.260502 -0.133561"/>
      <geometry>
        <mesh filename="package://eoat_description/meshes/LARGE_PAD_LIFTER_1.stl" scale="0.001 0.001 0.001"/>
      </geometry>
    </collision>
  </link>
  <link name="SMALL_PAD_LIFTER_1">
    <inertial>
      <origin rpy="0 0 0" xyz="0.038585639133993 0.03725443859840258 0.12440700695971876"/>
      <mass value="5.131967588982711"/>
      <inertia ixx="0.01009" ixy="5.5e-05" ixz="-1.3e-05" iyy="0.01215" iyz="0.001465" izz="0.009503"/>
    </inertial>
    <visual>
      <origin rpy="0 0 0" xyz="0.040088 0.062833 -0.075541"/>
      <geometry>
        <mesh filename="package://eoat_description/meshes/SMALL_PAD_LIFTER_1.stl" scale="0.001 0.001 0.001"/>
      </geometry>
      <material name="paint_metallic_red"/>
    </visual>
    <collision>
      <origin rpy="0 0 0" xyz="0.040088 0.062833 -0.075541"/>
      <geometry>
        <mesh filename="package://eoat_description/meshes/SMALL_PAD_LIFTER_1.stl" scale="0.001 0.001 0.001"/>
      </geometry>
    </collision>
  </link>
  <link name="SMALL_PAD_1">
    <inertial>
      <origin rpy="0 0 0" xyz="-0.03897023151560615 -0.00026688633084927076 0.12961367871119145"/>
      <mass value="7.67930271069137"/>
      <inertia ixx="0.021317" ixy="-1e-05" ixz="2e-06" iyy="0.028823" iyz="-2.1e-05" izz="0.037858"/>
    </inertial>
    <visual>
      <origin rpy="0 0 0" xyz="-0.037322 0.004833 -0.148202"/>
      <geometry>
        <mesh filename="package://eoat_description/meshes/SMALL_PAD_1.stl" scale="0.001 0.001 0.001"/>
      </geometry>
      <material name="paint_metallic_silver"/>
    </visual>
    <collision>
      <origin rpy="0 0 0" xyz="-0.037322 0.004833 -0.148202"/>
      <geometry>
        <mesh filename="package://eoat_description/meshes/SMALL_PAD_1.stl" scale="0.001 0.001 0.001"/>
      </geometry>
    </collision>
  </link>
  <link name="LARGE_PAD_1">
    <inertial>
      <origin rpy="0 0 0" xyz="0.07995131190356848 -0.13296840070700255 0.005166199269273419"/>
      <mass value="11.366258677174615"/>
      <inertia ixx="0.072156" ixy="-0.0" ixz="-2.8e-05" iyy="0.030353" iyz="0.002558" izz="0.089017"/>
    </inertial>
    <visual>
      <origin rpy="0 0 0" xyz="0.081678 0.142833 -0.210041"/>
      <geometry>
        <mesh filename="package://eoat_description/meshes/LARGE_PAD_1.stl" scale="0.001 0.001 0.001"/>
      </geometry>
      <material name="paint_metallic_silver"/>
    </visual>
    <collision>
      <origin rpy="0 0 0" xyz="0.081678 0.142833 -0.210041"/>
      <geometry>
        <mesh filename="package://eoat_description/meshes/LARGE_PAD_1.stl" scale="0.001 0.001 0.001"/>
      </geometry>
    </collision>
  </link>
  <link name="camera_1">
    <inertial>
      <origin rpy="0 0 0" xyz="-0.04819469681953277 0.03230748663147348 -0.004147639356130328"/>
      <mass value="3.034444752554033"/>
      <inertia ixx="0.00224" ixy="1e-06" ixz="0.000132" iyy="0.003128" iyz="-1e-06" izz="0.004062"/>
    </inertial>
    <visual>
      <origin rpy="0 0 0" xyz="-0.048322 0.407133 -0.165041"/>
      <geometry>
        <mesh filename="package://eoat_description/meshes/camera_1.stl" scale="0.001 0.001 0.001"/>
      </geometry>
      <material name="polymide_kapton"/>
    </visual>
    <collision>
      <origin rpy="0 0 0" xyz="-0.048322 0.407133 -0.165041"/>
      <geometry>
        <mesh filename="package://eoat_description/meshes/camera_1.stl" scale="0.001 0.001 0.001"/>
      </geometry>
    </collision>
  </link>
  <joint name="boxSupport_joint" type="prismatic">
    <origin rpy="0 0 0" xyz="0.08 -0.117669 -0.07648"/>
    <parent link="LARGE_PAD_1"/>
    <child link="LARGE_PAD_LIFTER_1"/>
    <axis xyz="0.0 -0.008691 -0.999962"/>
    <limit effort="100" lower="-0.01" upper="0.04" velocity="100"/>
  </joint>
  <joint name="suctionLifter_joint" type="prismatic">
    <origin rpy="0 0 0" xyz="-0.040088 -0.062833 0.075541"/>
    <parent link="base_link"/>
    <child link="SMALL_PAD_LIFTER_1"/>
    <axis xyz="-0.0 -0.0 -1.0"/>
    <limit effort="100" lower="-0.05" upper="0.0" velocity="100"/>
  </joint>
  <joint name="suction_joint" type="prismatic">
    <origin rpy="0 0 0" xyz="0.07741 0.058 0.072661"/>
    <parent link="SMALL_PAD_LIFTER_1"/>
    <child link="SMALL_PAD_1"/>
    <axis xyz="0.0 -0.0 1.0"/>
    <limit effort="100" lower="-0.015" upper="0.05" velocity="100"/>
  </joint>
  <joint name="padRotate_joint" type="revolute">
    <origin rpy="0 0 0" xyz="-0.081678 -0.142833 0.210041"/>
    <parent link="base_link"/>
    <child link="LARGE_PAD_1"/>
    <axis xyz="1.0 0.0 0.0"/>
    <limit effort="100" lower="-1.570796" upper="0.0" velocity="100"/>
  </joint>
  <joint name="cxamera_joint " type="fixed">
    <origin rpy="0 0 0" xyz="0.048322 -0.407133 0.165041"/>
    <parent link="base_link"/>
    <child link="camera_1"/>
  </joint>
</robot>
